Workbook
Name a: #REF!
Name Water_Parameters: #REF!
Name Water_Parameters: #REF!
Name Water_Parameters: #REF!

Sheet Word file
H10: Wex Tech
A11: =MakeUp!A9 -> 41369
A19: COOLING WATER TREATMENT
A21: DCM SRIRAM LIMITED
A23: MONTHLY REPORT
C44: REPORT
C45: OF
C46: COOLING TOWER
A70: DATE : | C70: =MakeUp!A9+32 -> 41401
A71: Sriram Chemical Ltd.,
A72: Jagadia, Ankleshwar
A73: Gujarat
A75: Kind Attn : Sh. K. R. Vaidya (Unit Head)
A76: Subject : Cooling Water Treatment Monthly Report
A79: Dear Sir,
A80: Please find enclosed herewith the CWT Monthly Report for your
A81: Cooling water system for the Month of | N81: =A11 -> 41369
A83: The report is based on the laboratory analysis done by our | J83: =A11 -> 41369
A84: representative in presence of your laboratory in charge and data
A85: collected from the Control Room.
A86: If you need any clarification, please feel free to contact us.
A87: Assuring you of our best services at all times.
A88: Thanking you,
A89: Yours sincerely,
A90: FOR WEX TECHNOLOGIES PVT. LTD.
A92: Vipul Govekar
A93: Regional Manager
A94: Encl. : a/a | B94: : a/a
A95: C.C. : MR. R. R. BULDAK
A96: MR. NAVIN JAISWAL
A97: MR. U. D. MEHTA
A98: MR. SUNIT GUPTA
A99: MR. ATUL CHOKSI
A102: EXECUTIVE SUMMARY
A103: 1] | B103: EXCEPTIONS CIRCULATING WATER PARAMETERS
A104: • | B104: pH was very well maintained within the specified limits throughout the month.
A105: • | B105: Turbidity was also very well maintained within its specified limits throughout the month.
A106: • | B106: FRC was reported on lower side on three occasions due to unavailability of chlorine toner. We request to ensure availability of spare toner at site all the time.
A107: • | B107: Conductivity was well maintained within the specified limits.
A108: • | B108: Total Hardness well maintained within its specified limits.
...

Sheet MakeUp
A1: MAKE UP WATER ANALYSIS
A3: Date | B3: pH | C3: Turb. | D3: Cond | E3: TDS | F3: TH | G3: CaH | H3: Cl | I3: Silica | J3: T. Alk. | K3: P. Alk.
A4: Unit | B4: -- | C4: NTU | D4: us/cm | E4: ppm | F4: ppm | G4: ppm | H4: ppm | I4: ppm | J4: ppm | K4: ppm
A5: 41365 | B5: 8.03 | C5: 3 | D5: 325 | E5: 220 | F5: 128 | G5: 71 | H5: 28 | I5: 20 | J5: 165 | K5: NIL
A6: 41366 | B6: 8.08 | C6: 3 | D6: 365 | E6: 180 | F6: 122 | G6: 70 | H6: 25 | I6: 20 | J6: 170 | K6: NIL
A7: 41367 | B7: 8.05 | C7: 2 | D7: 258 | E7: 175 | F7: 120 | G7: 70 | H7: 25 | I7: 18 | J7: 165 | K7: NIL
A8: 41368 | B8: 8.01 | C8: 2 | D8: 273 | E8: 185 | F8: 125 | G8: 71 | H8: 26 | I8: 18 | J8: 165 | K8: NIL
A9: 41369 | B9: 8.07 | C9: 2 | D9: 266 | E9: 180 | F9: 122 | G9: 70 | H9: 26 | I9: 19 | J9: 170 | K9: NIL
A10: 41370 | B10: 8.12 | C10: 2 | D10: 280 | E10: 190 | F10: 123 | G10: 70 | H10: 25 | I10: 19 | J10: 172 | K10: NIL
A11: 41371 | B11: 8.1 | C11: 3 | D11: 295 | E11: 200 | F11: 125 | G11: 71 | H11: 26 | I11: 19 | J11: 170 | K11: NIL
A12: 41372 | B12: 8.1 | C12: 3 | D12: 310 | E12: 210 | F12: 127 | G12: 72 | H12: 27 | I12: 20 | J12: 170 | K12: NIL
A13: 41373 | B13: 8.06 | C13: 3 | D13: 295 | E13: 200 | F13: 125 | G13: 71 | H13: 26 | I13: 20 | J13: 168 | K13: NIL
A14: 41374 | B14: 8.02 | C14: 3 | D14: 303 | E14: 205 | F14: 122 | G14: 70 | H14: 27 | I14: 20 | J14: 165 | K14: NIL
A15: 41375 | B15: 7.98 | C15: 2 | D15: 295 | E15: 200 | F15: 121 | G15: 70 | H15: 26 | I15: 19 | J15: 162 | K15: NIL
A16: 41376 | B16: 8.05 | C16: 2 | D16: 273 | E16: 185 | F16: 122 | G16: 70 | H16: 25 | I16: 19 | J16: 165 | K16: NIL
... A34: 41394 | B34: 8.02 | C34: 2 | D34: 269 | E34: 182 | F34: 117 | G34: 68 | H34: 16 | I34: 18 | J34: 165 | K34: NIL
A36: MIN. | B36: =MIN(B5:B35) -> 7.8 | C36: =MIN(C5:C35) -> 2 | D36: =MIN(D5:D35) -> 250 | E36: =MIN(E5:E35) -> 170 | F36: =MIN(F5:F35) -> 112 | G36: =MIN(G5:G35) -> 66 | H36: 36 | I36: =MIN(I5:I35) -> 17 | J36: =MIN(J5:J35) -> 155 | K36: NIL
A37: MAX. | B37: =MAX(B5:B35) -> 8.12 | C37: =MAX(C5:C35) -> 3 | D37: =MAX(D5:D35) -> 365 | E37: =MAX(E5:E35) -> 220 | F37: =MAX(F5:F35) -> 128 | G37: =MAX(G5:G35) -> 72 | H37: 36 | I37: =MAX(I5:I35) -> 21 | J37: =MAX(J5:J35) -> 172 | K37: NIL
A38: AVG. | B38: =AVERAGE(B5:B35) -> 8.0116667 | C38: =AVERAGE(C5:C35) -> 2.3666667 | D38: =AVERAGE(D5:D35) -> 283.76667 | E38: =AVERAGE(E5:E35) -> 190.33333 | F38: =AVERAGE(F5:F35) -> 120.46667 | G38: =AVERAGE(G5:G35) -> 69.366667 | H38: 33 | I38: =AVERAGE(I5:I35) -> 18.966667 | J38: =AVERAGE(J5:J35) -> 164.83333 | K38: =AVERAGE(K5:K35) -> #DIV/0!

Sheet Cooling Tower
A1: CIRCULATING WATER ANALYSIS FOR COOLING TOWER
A3: DATE | B3: pH | C3: Turbidity | D3: FRC | E3: COND | F3: TDS | G3: TH | H3: CaH | I3: MgH | J3: Cl | K3: Ortho PO4 | L3: T. Alk. | M3: P. Alk. | N3: Total Iron | O3: SS | P3: Sulphate | Q3: Silica
B4: 7.5-8.0 | C4: Max. 20 NTU | D4: 0.2 - 0.5 ppm | E4: umho/cm | F4: Max. 2100 ppm | G4: Max. 1200 ppm | H4: ppm | I4: ppm | J4: Max. 500 ppm | K4: 4.0 - 6.0 ppm | L4: Max. 200 ppm | M4: 0 ppm | N4: Max. 2 ppm | O4: ppm | P4: Max. 1000 ppm | Q4: 180 ppm
A5: =MakeUp!A5 -> 41365 | B5: 7.59 | C5: 121 | D5: 0.2 | E5: 2390 | F5: 1618 | G5: 1102 | H5: 672 | I5: =G5-H5 -> 430 | J5: 146 | K5: 6.5 | L5: 120 | M5: NIL | N5: 0.2 | O5: 240 | P5: 893 | Q5: 95
A6: =MakeUp!A6 -> 41366 | B6: 7.86 | C6: 118 | D6: 0.2 | E6: 2190 | F6: 1479 | G6: 918 | H6: 560 | I6: =G6-H6 -> 358 | J6: 125 | K6: 7.2 | L6: 150 | M6: NIL | N6: 0.2 | O6: 236 | P6: 984 | Q6: 91
A7: =MakeUp!A7 -> 41367 | B7: 7.92 | C7: 104 | D7: 0.2 | E7: 2100 | F7: 1420 | G7: 898 | H7: 530 | I7: =G7-H7 -> 368 | J7: 132 | K7: 6.8 | L7: 160 | M7: NIL | N7: 0.2 | O7: 208 | P7: 916 | Q7: 98
A8: =MakeUp!A8 -> 41368 | B8: 7.98 | C8: 85 | D8: 0.2 | E8: 2180 | F8: 1470 | G8: 877 | H8: 510 | I8: =G8-H8 -> 367 | J8: 125 | K8: 8 | L8: 165 | M8: NIL | N8: 0.2 | O8: 170 | P8: 966 | Q8: 110
A9: =MakeUp!A9 -> 41369 | B9: 7.9 | C9: 77 | D9: 0.2 | E9: 2150 | F9: 1450 | G9: 816 | H9: 449 | I9: =G9-H9 -> 367 | J9: 114 | K9: 7.1 | L9: 160 | M9: NIL | N9: 0.2 | O9: 154 | P9: 952 | Q9: 113
A10: =MakeUp!A10 -> 41370 | B10: 7.8 | C10: 62 | D10: 0.2 | E10: 2010 | F10: 1360 | G10: 775 | H10: 428 | I10: =G10-H10 -> 347 | J10: 110 | K10: 7 | L10: 150 | M10: NIL | N10: 0.2 | O10: 120 | P10: 938 | Q10: 108
A11: =MakeUp!A11 -> 41371 | B11: 8.02 | C11: 50 | D11: 0.2 | E11: 2000 | F11: 1353 | G11: 672 | H11: 401 | I11: =G11-H11 -> 271 | J11: 103 | K11: 7 | L11: 170 | M11: NIL | N11: 0.2 | O11: 98 | P11: 942 | Q11: 110
A12: =MakeUp!A12 -> 41372 | B12: 8 | C12: 49 | D12: 0.2 | E12: 1995 | F12: 1348 | G12: 726 | H12: 416 | I12: =G12-H12 -> 310 | J12: 114 | K12: 7 | L12: 170 | M12: NIL | N12: 0.2 | O12: 90 | P12: 956 | Q12: 112
A13: =MakeUp!A13 -> 41373 | B13: 7.9 | C13: 41 | D13: 0.2 | E13: 2050 | F13: 1431 | G13: 747 | H13: 428 | I13: =G13-H13 -> 319 | J13: 117 | K13: 6.9 | L13: 160 | M13: NIL | N13: 0.2 | O13: 80 | P13: 943 | Q13: 110
A14: =MakeUp!A14 -> 41374 | B14: 7.88 | C14: 52 | D14: 0.1 | E14: 2215 | F14: 1550 | G14: 726 | H14: 420 | I14: =G14-H14 -> 306 | J14: 114 | K14: 6.8 | L14: 160 | M14: NIL | N14: 0.2 | O14: 101 | P14: 929 | Q14: 108
A15: =MakeUp!A15 -> 41375 | B15: 8.09 | C15: 45 | D15: 0.2 | E15: 1740 | F15: 1218 | G15: 734 | H15: 428 | I15: =G15-H15 -> 306 | J15: 117 | K15: 7 | L15: 170 | M15: NIL | N15: 0.2 | O15: 88 | P15: 910 | Q15: 110
A16: =MakeUp!A16 -> 41376 | B16: 7.98 | C16: 37 | D16: 0.2 | E16: 1795 | F16: 1256 | G16: 747 | H16: 428 | I16: =G16-H16 -> 319 | J16: 125 | K16: 6.8 | L16: 170 | M16: NIL | N16: 0.2 | O16: 74 | P16: 925 | Q16: 108
... A34: =MakeUp!A34 -> 41394 | B34: 7.98 | C34: 24 | D34: 0.2 | E34: 2427 | F34: 1699 | G34: 899 | H34: 556 | I34: =G34-H34 -> 343 | J34: 153 | K34: 7.2 | L34: 170 | M34: NIL | N34: 0.2 | O34: 44 | P34: 918 | Q34: 110
A36: =MakeUp!A36 -> MIN. | B36: =MIN(B5:B35) -> 7.59 | C36: =MIN(C5:C35) -> 18 | D36: =MIN(D5:D35) -> 0.1 | E36: =MIN(E5:E35) -> 1740 | F36: =MIN(F5:F35) -> 1218 | G36: =MIN(G5:G35) -> 672 | H36: =MIN(H5:H35) -> 401 | I36: =MIN(I5:I35) -> 224 | ... Q36: =MIN(Q5:Q35) -> 91
A37: =MakeUp!A37 -> MAX. | B37: =MAX(B5:B35) -> 8.12 | C37: =MAX(C5:C35) -> 121 | D37: =MAX(D5:D35) -> 0.2 | E37: =MAX(E5:E35) -> 2880 | F37: =MAX(F5:F35) -> 1995 | G37: =MAX(G5:G35) -> 1102 | H37: =MAX(H5:H35) -> 694 | I37: =MAX(I5:I35) -> 458 | ... Q37: =MAX(Q5:Q35) -> 121
A38: =MakeUp!A38 -> AVG. | B38: =AVERAGE(B5:B35) -> 7.939 | C38: =AVERAGE(C5:C35) -> 45.833333 | D38: =AVERAGE(D5:D35) -> 0.19666667 | E38: =AVERAGE(E5:E35) -> 2251.8 | F38: =AVERAGE(F5:F35) -> 1560.4 | G38: =AVERAGE(G5:G35) -> 904.43333 | H38: =AVERAGE(H5:H35) -> 538.83333 | I38: =AVERAGE(I5:I35) -> 365.6 | ... Q38: =AVERAGE(Q5:Q35) -> 109.03333
A39: No. of < Spec | B39: =COUNTIF(B5:B35,"<7.5") -> 0 | C39: -- | D39: =COUNTIF(D5:D35,"<0.2") -> 1 | E39: -- | F39: -- | G39: -- | H39: -- | I39: -- | J39: -- | K39: =COUNTIF(K5:K35,"<4") -> 0 | L39: -- | M39: -- | N39: -- | O39: -- | P39: -- | Q39: --
A40: No. of > Spec | B40: =COUNTIF(B5:B35,">8.0") -> 6 | C40: =COUNTIF(C5:C35,">20") -> 28 | D40: =COUNTIF(D5:D35,">0.5") -> 0 | E40: -- | F40: =COUNTIF(F5:F35,">2100") -> 0 | G40: =COUNTIF(G5:G35,">1200") -> 0 | H40: -- | I40: -- | J40: =COUNTIF(J5:J35,">500") -> 0 | K40: =COUNTIF(K5:K35,">6.0") -> 27 | L40: =COUNTIF(L5:L35,">200") -> 0 | M40: -- | N40: =COUNTIF(N5:N35,">2.0") -> 0 | O40: -- | P40: =COUNTIF(P5:P35,">1000") -> 0 | Q40: =COUNTIF(Q5:Q35,">180") -> 0
A41: % < Specs. | B41: =(100/(COUNT(B5:B35)))*B39 -> 0 | C41: -- | D41: =(100/(COUNT(D5:D35)))*D39 -> 3.3333333 | E41: -- | F41: -- | G41: -- | H41: -- | I41: -- | J41: -- | K41: =(100/(COUNT(K5:K35)))*K39 -> 0 | L41: =(100/(COUNT(L5:L35)))*L39 -> #VALUE! | M41: =(100/(COUNT(M5:M35)))*M39 -> #DIV/0! | N41: =(100/(COUNT(N5:N35)))*N39 -> #VALUE! | O41: =(100/(COUNT(O5:O35)))*O39 -> #VALUE! | P41: =(100/(COUNT(P5:P35)))*P39 -> #VALUE! | Q41: --
A42: % > Specs. | B42: =(100/(COUNT(B5:B35)))*B40 -> 20 | C42: =(100/(COUNT(C5:C35)))*C40 -> 93.333333 | D42: =(100/(COUNT(D5:D35)))*D40 -> 0 | E42: =(100/(COUNT(E5:E35)))*E40 -> #VALUE! | F42: =(100/(COUNT(F5:F35)))*F40 -> 0 | G42: =(100/(COUNT(G5:G35)))*G40 -> 0 | H42: =(100/(COUNT(H5:H35)))*H40 -> #VALUE! | I42: -- | J42: =(100/(COUNT(J5:J35)))*J40 -> 0 | K42: =(100/(COUNT(K5:K35)))*K40 -> 90 | L42: =(100/(COUNT(L5:L35)))*L40 -> 0 | M42: =(100/(COUNT(M5:M35)))*M40 -> #DIV/0! | N42: =(100/(COUNT(N5:N35)))*N40 -> 0 | O42: =(100/(COUNT(O5:O35)))*O40 -> #VALUE! | P42: =(100/(COUNT(P5:P35)))*P40 -> 0 | Q42: =(100/(COUNT(Q5:Q35)))*Q40 -> 0

Sheet Operational Parameters
A1: Power Plant Data & Operational Parameters
A2: Date | B2: Plant Load | C2: Vacumm | D2: COC Based on (TH) | E2: COC Based on (Silica) | F2: CT Blowdown
B3: MW | C3: Kgs./Cm2 | F3: M3/Hr.
A4: =MakeUp!A5 -> 41365 | D4: ='Cooling Tower'!G5/MakeUp!F5 -> 8.609375 | E4: ='Cooling Tower'!Q5/MakeUp!I5 -> 4.75
A5: =MakeUp!A6 -> 41366 | D5: ='Cooling Tower'!G6/MakeUp!F6 -> 7.5245902 | E5: ='Cooling Tower'!Q6/MakeUp!I6 -> 4.55
A6: =MakeUp!A7 -> 41367 | D6: ='Cooling Tower'!G7/MakeUp!F7 -> 7.4833333 | E6: ='Cooling Tower'!Q7/MakeUp!I7 -> 5.4444444
A7: =MakeUp!A8 -> 41368 | D7: ='Cooling Tower'!G8/MakeUp!F8 -> 7.016 | E7: ='Cooling Tower'!Q8/MakeUp!I8 -> 6.1111111
A8: =MakeUp!A9 -> 41369 | D8: ='Cooling Tower'!G9/MakeUp!F9 -> 6.6885246 | E8: ='Cooling Tower'!Q9/MakeUp!I9 -> 5.9473684
A9: =MakeUp!A10 -> 41370 | D9: ='Cooling Tower'!G10/MakeUp!F10 -> 6.300813 | E9: ='Cooling Tower'!Q10/MakeUp!I10 -> 5.6842105
A10: =MakeUp!A11 -> 41371 | D10: ='Cooling Tower'!G11/MakeUp!F11 -> 5.376 | E10: ='Cooling Tower'!Q11/MakeUp!I11 -> 5.7894737
A11: =MakeUp!A12 -> 41372 | D11: ='Cooling Tower'!G12/MakeUp!F12 -> 5.7165354 | E11: ='Cooling Tower'!Q12/MakeUp!I12 -> 5.6
A12: =MakeUp!A13 -> 41373 | D12: ='Cooling Tower'!G13/MakeUp!F13 -> 5.976 | E12: ='Cooling Tower'!Q13/MakeUp!I13 -> 5.5
A13: =MakeUp!A14 -> 41374 | D13: ='Cooling Tower'!G14/MakeUp!F14 -> 5.9508197 | E13: ='Cooling Tower'!Q14/MakeUp!I14 -> 5.4
A14: =MakeUp!A15 -> 41375 | D14: ='Cooling Tower'!G15/MakeUp!F15 -> 6.0661157 | E14: ='Cooling Tower'!Q15/MakeUp!I15 -> 5.7894737
A15: =MakeUp!A16 -> 41376 | D15: ='Cooling Tower'!G16/MakeUp!F16 -> 6.1229508 | E15: ='Cooling Tower'!Q16/MakeUp!I16 -> 5.6842105
... A34: =MakeUp!A35 -> 0 | D34: ='Cooling Tower'!G35/MakeUp!F35 -> #DIV/0! | E34: ='Cooling Tower'!Q35/MakeUp!I35 -> #DIV/0!
A35: ='Cooling Tower'!A36 -> MIN. | B35: =MIN(B4:B34) -> 0 | C35: =MIN(C4:C34) -> 0 | D35: =MIN(D4:D34) -> #DIV/0! | E35: =MIN(E4:E34) -> #DIV/0! | F35: =MIN(F4:F34) -> 0
A36: ='Cooling Tower'!A37 -> MAX. | B36: =MAX(B4:B34) -> 0 | C36: =MAX(C4:C34) -> 0 | D36: =MAX(D4:D34) -> #DIV/0! | E36: =MAX(E4:E34) -> #DIV/0! | F36: =MAX(F4:F34) -> 0
A37: ='Cooling Tower'!A38 -> AVG. | B37: =AVERAGE(B4:B34) -> #DIV/0! | C37: =AVERAGE(C4:C34) -> #DIV/0! | D37: =AVERAGE(D4:D34) -> #DIV/0! | E37: =AVERAGE(E4:E34) -> #DIV/0! | F37: =AVERAGE(F4:F34) -> #DIV/0!

Sheet CT Parameter Graphs

Sheet Operational Graphs

Sheet Chemical Consumption
A2: Chemical Consumption for Cooling Tower
A3: Sr. No. | B3: Chemical Name | C3: Specified Monthly Consumption (Kgs.) | D3: Opening Stock (Kgs.) | G3: Receipt in Store (Kgs.) | H3: Actual Consumption (Kgs.) | I3: Closing Balance (Kgs.)
D4: At Store | E4: At Utility | F4: Total Stock | I4: At Store | J4: At Utility | K4: Total Stock
A5: 1
A6: 2
A7: 3
A8: 4
A9: 5
A10: 6
